Internal Server Error: /reports/detailed_supervisor_report/16/
Traceback (most recent call last):
  File "/usr/local/lib/python3.10/site-packages/django/core/handlers/exception.py", line 55, in inner
    response = get_response(request)
  File "/usr/local/lib/python3.10/site-packages/django/core/handlers/base.py", line 197, in _get_response
    response = wrapped_callback(request, *callback_args, **callback_kwargs)
  File "/code/reports/views.py", line 19, in detailed_supervisor_report
    detailed_report = SupervisorReport.detailed(fleet.id, start_date, end_date)
  File "/code/reports/models.py", line 44, in detailed
    test_line_plot = ReportUtils.plotly_line_plot_test(
  File "/code/reports/ReportUtils.py", line 33, in plotly_line_plot_test
    chart = fig.to_image()
  File "/usr/local/lib/python3.10/site-packages/plotly/basedatatypes.py", line 3766, in to_image
    return pio.to_image(self, *args, **kwargs)
  File "/usr/local/lib/python3.10/site-packages/plotly/io/_kaleido.py", line 134, in to_image
    raise ValueError(
ValueError: 
Image export using the "kaleido" engine requires the kaleido package,
which can be installed using pip:
    $ pip install -U kaleido

Not Found: /favicon.ico
Not Found: /favicon.ico
Not Found: /favicon.ico
